2025-04-11T00:51:47.739919+0300 ERROR Ошибка при очистке кэша: Error -2 connecting to default_host:6379. -2.
2025-04-11T00:56:00.152969+0300 ERROR Ошибка при очистке кэша: Error -2 connecting to default_host:6379. -2.
2025-04-11T00:56:06.155184+0300 ERROR Ошибка при очистке кэша: Error -2 connecting to default_host:6379. -2.
2025-04-11T00:56:11.679596+0300 ERROR Ошибка при очистке кэша: Error -2 connecting to default_host:6379. -2.
2025-04-11T00:56:16.289214+0300 ERROR Ошибка при очистке кэша: Error -2 connecting to default_host:6379. -2.
2025-04-11T00:57:32.042286+0300 ERROR Ошибка при очистке кэша: Error -2 connecting to default_host:6379. -2.
2025-04-11T01:02:24.700544+0300 ERROR Ошибка при очистке кэша: Error -2 connecting to default_host:6379. -2.
2025-04-11T01:02:29.710089+0300 ERROR Ошибка при очистке кэша: Error -2 connecting to default_host:6379. -2.
2025-04-11T01:02:31.226803+0300 ERROR Ошибка при очистке кэша: Error -2 connecting to default_host:6379. -2.
2025-04-11T01:03:13.174924+0300 ERROR Ошибка при очистке кэша: Error -2 connecting to default_host:6379. -2.
2025-04-11T01:14:34.380828+0300 ERROR Ошибка при очистке кэша: Error -2 connecting to default_host:6379. -2.
2025-04-11T01:15:29.900960+0300 ERROR Ошибка при очистке кэша: Error -2 connecting to default_host:6379. -2.
2025-04-11T01:16:07.410620+0300 ERROR Ошибка при очистке кэша: Error -2 connecting to default_host:6379. -2.
2025-04-11T01:19:57.554842+0300 ERROR Ошибка при очистке кэша: Error -2 connecting to default_host:6379. -2.
2025-04-11T01:37:13.272714+0300 ERROR Ошибка при очистке кэша: Error -2 connecting to default_host:6379. -2.
2025-04-11T01:37:19.155038+0300 ERROR Ошибка при очистке кэша: Error -2 connecting to default_host:6379. -2.
2025-04-11T01:37:54.898429+0300 ERROR Ошибка при очистке кэша: Error -2 connecting to default_host:6379. -2.
2025-04-11T01:39:35.152892+0300 ERROR Ошибка при очистке кэша: Error -2 connecting to default_host:6379. -2.
2025-04-11T01:39:59.793877+0300 ERROR Ошибка при очистке кэша: Error -2 connecting to default_host:6379. -2.
2025-04-11T01:40:02.819469+0300 ERROR Ошибка при очистке кэша: Error -2 connecting to default_host:6379. -2.
2025-04-11T01:48:41.472989+0300 ERROR Ошибка при очистке кэша: Error -2 connecting to default_host:6379. -2.
2025-04-11T01:48:47.443554+0300 ERROR Ошибка при очистке кэша: Error -2 connecting to default_host:6379. -2.
2025-04-11T01:48:55.784234+0300 ERROR Ошибка при очистке кэша: Error -2 connecting to default_host:6379. -2.
2025-04-11T01:52:21.921623+0300 ERROR Ошибка при очистке кэша: Error -2 connecting to default_host:6379. -2.
2025-04-11T01:52:27.935709+0300 ERROR Ошибка при очистке кэша: Error -2 connecting to default_host:6379. -2.
2025-04-11T01:52:33.954349+0300 ERROR Ошибка при очистке кэша: Error -2 connecting to default_host:6379. -2.
2025-04-11T01:53:13.500289+0300 ERROR Ошибка при очистке кэша: Error -2 connecting to default_host:6379. -2.
2025-04-11T01:54:29.201965+0300 ERROR Ошибка при очистке кэша: Error -2 connecting to default_host:6379. -2.
2025-04-11T01:54:33.926832+0300 ERROR Ошибка при очистке кэша: Error -2 connecting to default_host:6379. -2.
2025-04-11T01:54:39.256589+0300 ERROR Ошибка при очистке кэша: Error -2 connecting to default_host:6379. -2.
2025-04-11T01:57:44.910110+0300 ERROR Ошибка при очистке кэша: Error -2 connecting to default_host:6379. -2.
2025-04-11T01:58:17.336255+0300 ERROR Ошибка при очистке кэша: Error -2 connecting to default_host:6379. -2.
2025-04-11T01:59:00.544872+0300 ERROR Ошибка при очистке кэша: Error -2 connecting to default_host:6379. -2.
2025-04-11T01:59:13.923094+0300 ERROR Ошибка при очистке кэша: Error -2 connecting to default_host:6379. -2.
2025-04-11T01:59:33.748375+0300 ERROR Ошибка при очистке кэша: Error -2 connecting to default_host:6379. -2.
2025-04-11T01:59:36.374763+0300 ERROR Ошибка при очистке кэша: Error -2 connecting to default_host:6379. -2.
2025-04-11T01:59:42.768468+0300 ERROR Ошибка при очистке кэша: Error -2 connecting to default_host:6379. -2.
2025-04-11T01:59:45.535064+0300 ERROR Ошибка при очистке кэша: Error -2 connecting to default_host:6379. -2.
2025-04-11T01:59:54.307341+0300 ERROR Ошибка при очистке кэша: Error -2 connecting to default_host:6379. -2.
2025-04-11T01:59:56.805723+0300 ERROR Ошибка при очистке кэша: Error -2 connecting to default_host:6379. -2.
2025-04-11T02:00:00.904213+0300 ERROR Ошибка при очистке кэша: Error -2 connecting to default_host:6379. -2.
2025-04-11T02:00:04.519927+0300 ERROR Ошибка при очистке кэша: Error -2 connecting to default_host:6379. -2.
2025-04-11T02:00:07.359406+0300 ERROR Ошибка при очистке кэша: Error -2 connecting to default_host:6379. -2.
2025-04-11T02:01:09.307622+0300 ERROR Ошибка при очистке кэша: Error -2 connecting to default_host:6379. -2.
2025-04-11T02:09:18.030216+0300 ERROR Ошибка при очистке кэша: Error -2 connecting to default_host:6379. -2.
2025-04-11T02:09:24.398784+0300 ERROR Ошибка при очистке кэша: Error -2 connecting to default_host:6379. -2.
2025-04-11T09:56:46.450643+0300 ERROR Cache invalidation error: Traceback (most recent call last):
  File "/home/slsforme/Programming/python/fastapi/priroda_razuma/env/lib/python3.12/site-packages/redis/asyncio/connection.py", line 577, in connect
    await self.retry.call_with_retry(
  File "/home/slsforme/Programming/python/fastapi/priroda_razuma/env/lib/python3.12/site-packages/redis/asyncio/retry.py", line 59, in call_with_retry
    return await do()
           ^^^^^^^^^^
  File "/home/slsforme/Programming/python/fastapi/priroda_razuma/env/lib/python3.12/site-packages/redis/asyncio/connection.py", line 922, in _connect
    reader, writer = await asyncio.open_connection(
                     ^^^^^^^^^^^^^^^^^^^^^^^^^^^^^^
  File "/home/slsforme/.pyenv/versions/3.12.0/lib/python3.12/asyncio/streams.py", line 47, in open_connection
    transport, _ = await loop.create_connection(
                   ^^^^^^^^^^^^^^^^^^^^^^^^^^^^^
  File "uvloop/loop.pyx", line 1982, in create_connection
socket.gaierror: [Errno -3] Temporary failure in name resolution

During handling of the above exception, another exception occurred:

Traceback (most recent call last):
  File "/home/slsforme/Programming/python/fastapi/priroda_razuma/src/routing/base.py", line 41, in invalidate_cache
    all_keys = await redis.keys(f"{FastAPICache.get_prefix()}*")
               ^^^^^^^^^^^^^^^^^^^^^^^^^^^^^^^^^^^^^^^^^^^^^^^^^
  File "/home/slsforme/Programming/python/fastapi/priroda_razuma/env/lib/python3.12/site-packages/redis/asyncio/client.py", line 513, in execute_command
    conn = self.connection or await pool.get_connection(command_name, **options)
                              ^^^^^^^^^^^^^^^^^^^^^^^^^^^^^^^^^^^^^^^^^^^^^^^^^^
  File "/home/slsforme/Programming/python/fastapi/priroda_razuma/env/lib/python3.12/site-packages/redis/asyncio/connection.py", line 1375, in get_connection
    await connection.connect()
  File "/home/slsforme/Programming/python/fastapi/priroda_razuma/env/lib/python3.12/site-packages/redis/asyncio/connection.py", line 585, in connect
    raise ConnectionError(self._error_message(e))
redis.exceptions.ConnectionError: Error -3 connecting to default_host:6379. -3.

2025-04-11T09:56:55.492415+0300 ERROR Cache invalidation error: Traceback (most recent call last):
  File "/home/slsforme/Programming/python/fastapi/priroda_razuma/env/lib/python3.12/site-packages/redis/asyncio/connection.py", line 577, in connect
    await self.retry.call_with_retry(
  File "/home/slsforme/Programming/python/fastapi/priroda_razuma/env/lib/python3.12/site-packages/redis/asyncio/retry.py", line 59, in call_with_retry
    return await do()
           ^^^^^^^^^^
  File "/home/slsforme/Programming/python/fastapi/priroda_razuma/env/lib/python3.12/site-packages/redis/asyncio/connection.py", line 922, in _connect
    reader, writer = await asyncio.open_connection(
                     ^^^^^^^^^^^^^^^^^^^^^^^^^^^^^^
  File "/home/slsforme/.pyenv/versions/3.12.0/lib/python3.12/asyncio/streams.py", line 47, in open_connection
    transport, _ = await loop.create_connection(
                   ^^^^^^^^^^^^^^^^^^^^^^^^^^^^^
  File "uvloop/loop.pyx", line 1982, in create_connection
socket.gaierror: [Errno -3] Temporary failure in name resolution

During handling of the above exception, another exception occurred:

Traceback (most recent call last):
  File "/home/slsforme/Programming/python/fastapi/priroda_razuma/src/routing/base.py", line 41, in invalidate_cache
    all_keys = await redis.keys(f"{FastAPICache.get_prefix()}*")
               ^^^^^^^^^^^^^^^^^^^^^^^^^^^^^^^^^^^^^^^^^^^^^^^^^
  File "/home/slsforme/Programming/python/fastapi/priroda_razuma/env/lib/python3.12/site-packages/redis/asyncio/client.py", line 513, in execute_command
    conn = self.connection or await pool.get_connection(command_name, **options)
                              ^^^^^^^^^^^^^^^^^^^^^^^^^^^^^^^^^^^^^^^^^^^^^^^^^^
  File "/home/slsforme/Programming/python/fastapi/priroda_razuma/env/lib/python3.12/site-packages/redis/asyncio/connection.py", line 1375, in get_connection
    await connection.connect()
  File "/home/slsforme/Programming/python/fastapi/priroda_razuma/env/lib/python3.12/site-packages/redis/asyncio/connection.py", line 585, in connect
    raise ConnectionError(self._error_message(e))
redis.exceptions.ConnectionError: Error -3 connecting to default_host:6379. -3.

2025-04-11T09:57:27.694204+0300 ERROR Cache invalidation error: Traceback (most recent call last):
  File "/home/slsforme/Programming/python/fastapi/priroda_razuma/env/lib/python3.12/site-packages/redis/asyncio/connection.py", line 577, in connect
    await self.retry.call_with_retry(
  File "/home/slsforme/Programming/python/fastapi/priroda_razuma/env/lib/python3.12/site-packages/redis/asyncio/retry.py", line 59, in call_with_retry
    return await do()
           ^^^^^^^^^^
  File "/home/slsforme/Programming/python/fastapi/priroda_razuma/env/lib/python3.12/site-packages/redis/asyncio/connection.py", line 922, in _connect
    reader, writer = await asyncio.open_connection(
                     ^^^^^^^^^^^^^^^^^^^^^^^^^^^^^^
  File "/home/slsforme/.pyenv/versions/3.12.0/lib/python3.12/asyncio/streams.py", line 47, in open_connection
    transport, _ = await loop.create_connection(
                   ^^^^^^^^^^^^^^^^^^^^^^^^^^^^^
  File "uvloop/loop.pyx", line 1982, in create_connection
socket.gaierror: [Errno -3] Temporary failure in name resolution

During handling of the above exception, another exception occurred:

Traceback (most recent call last):
  File "/home/slsforme/Programming/python/fastapi/priroda_razuma/src/routing/base.py", line 41, in invalidate_cache
    all_keys = await redis.keys(f"{FastAPICache.get_prefix()}*")
               ^^^^^^^^^^^^^^^^^^^^^^^^^^^^^^^^^^^^^^^^^^^^^^^^^
  File "/home/slsforme/Programming/python/fastapi/priroda_razuma/env/lib/python3.12/site-packages/redis/asyncio/client.py", line 513, in execute_command
    conn = self.connection or await pool.get_connection(command_name, **options)
                              ^^^^^^^^^^^^^^^^^^^^^^^^^^^^^^^^^^^^^^^^^^^^^^^^^^
  File "/home/slsforme/Programming/python/fastapi/priroda_razuma/env/lib/python3.12/site-packages/redis/asyncio/connection.py", line 1375, in get_connection
    await connection.connect()
  File "/home/slsforme/Programming/python/fastapi/priroda_razuma/env/lib/python3.12/site-packages/redis/asyncio/connection.py", line 585, in connect
    raise ConnectionError(self._error_message(e))
redis.exceptions.ConnectionError: Error -3 connecting to default_host:6379. -3.

2025-04-11T09:57:28.339314+0300 ERROR Cache invalidation error: Traceback (most recent call last):
  File "/home/slsforme/Programming/python/fastapi/priroda_razuma/env/lib/python3.12/site-packages/redis/asyncio/connection.py", line 577, in connect
    await self.retry.call_with_retry(
  File "/home/slsforme/Programming/python/fastapi/priroda_razuma/env/lib/python3.12/site-packages/redis/asyncio/retry.py", line 59, in call_with_retry
    return await do()
           ^^^^^^^^^^
  File "/home/slsforme/Programming/python/fastapi/priroda_razuma/env/lib/python3.12/site-packages/redis/asyncio/connection.py", line 922, in _connect
    reader, writer = await asyncio.open_connection(
                     ^^^^^^^^^^^^^^^^^^^^^^^^^^^^^^
  File "/home/slsforme/.pyenv/versions/3.12.0/lib/python3.12/asyncio/streams.py", line 47, in open_connection
    transport, _ = await loop.create_connection(
                   ^^^^^^^^^^^^^^^^^^^^^^^^^^^^^
  File "uvloop/loop.pyx", line 1982, in create_connection
socket.gaierror: [Errno -3] Temporary failure in name resolution

During handling of the above exception, another exception occurred:

Traceback (most recent call last):
  File "/home/slsforme/Programming/python/fastapi/priroda_razuma/src/routing/base.py", line 41, in invalidate_cache
    all_keys = await redis.keys(f"{FastAPICache.get_prefix()}*")
               ^^^^^^^^^^^^^^^^^^^^^^^^^^^^^^^^^^^^^^^^^^^^^^^^^
  File "/home/slsforme/Programming/python/fastapi/priroda_razuma/env/lib/python3.12/site-packages/redis/asyncio/client.py", line 513, in execute_command
    conn = self.connection or await pool.get_connection(command_name, **options)
                              ^^^^^^^^^^^^^^^^^^^^^^^^^^^^^^^^^^^^^^^^^^^^^^^^^^
  File "/home/slsforme/Programming/python/fastapi/priroda_razuma/env/lib/python3.12/site-packages/redis/asyncio/connection.py", line 1375, in get_connection
    await connection.connect()
  File "/home/slsforme/Programming/python/fastapi/priroda_razuma/env/lib/python3.12/site-packages/redis/asyncio/connection.py", line 585, in connect
    raise ConnectionError(self._error_message(e))
redis.exceptions.ConnectionError: Error -3 connecting to default_host:6379. -3.

